Workbook
Name ColumnTitle2: הפחתה23[[#Headers],[מס'']]
Name ColumnTitle2: הפחתה[[#Headers],[מס'']]
Name ColumnTitle2: הפחתה[[#Headers],[מס'']]
Name HeaderRow: ROW(' טבלת סילוקין - מסכמת'!$B$3:$J$3)
Name HeaderRow: ROW(' טבלת סילוקין - לפי מסלולים'!$B$3:$J$3)
Name HeaderRow2: ROW(' טבלת סילוקין - מסכמת'!#REF!)
Name HeaderRow2: ROW(' טבלת סילוקין - לפי מסלולים'!$K$3:$S$3)
Name HeaderRow3: ROW(' טבלת סילוקין - מסכמת'!#REF!)
Name HeaderRow3: ROW(' טבלת סילוקין - לפי מסלולים'!$T$3:$AB$3)
Name HeaderRow4: ROW(' טבלת סילוקין - מסכמת'!#REF!)
Name HeaderRow4: ROW(' טבלת סילוקין - לפי מסלולים'!$AC$3:$AK$3)
Name LastRow: COUNTIF(' טבלת סילוקין - מסכמת'!$C$4:$C$363,">1")+' טבלת סילוקין - מסכמת'!HeaderRow
Name LastRow: COUNTIF(' טבלת סילוקין - לפי מסלולים'!$C$4:$C$363,">1")+HeaderRow
Name LastRow2: COUNTIF(' טבלת סילוקין - מסכמת'!#REF!,">1")+' טבלת סילוקין - מסכמת'!HeaderRow2
Name LastRow2: COUNTIF(' טבלת סילוקין - לפי מסלולים'!$L$4:$L$363,">1")+HeaderRow2
Name LastRow3: COUNTIF(' טבלת סילוקין - מסכמת'!#REF!,">1")+' טבלת סילוקין - מסכמת'!HeaderRow3
Name LastRow3: COUNTIF(' טבלת סילוקין - לפי מסלולים'!$U$4:$U$363,">1")+HeaderRow3
Name LastRow4: COUNTIF(' טבלת סילוקין - מסכמת'!#REF!,">1")+' טבלת סילוקין - מסכמת'!HeaderRow4
Name LastRow4: COUNTIF(' טבלת סילוקין - לפי מסלולים'!$AD$4:$AD$363,">1")+HeaderRow4
Name LoanIsGood: (דאשבורד!$C$4*דאשבורד!$C$5*דאשבורד!$C$6)>0
Name LoanIsGood: ('מחשבון משכנתה'!$C$4*'מחשבון משכנתה'!$C$5*'מחשבון משכנתה'!$C$6)>0
Name LoanIsGood2: (דאשבורד!#REF!*דאשבורד!#REF!*דאשבורד!#REF!)>0
Name LoanIsGood2: ('מחשבון משכנתה'!$L$4*'מחשבון משכנתה'!$L$5*'מחשבון משכנתה'!$L$6)>0
Name LoanStart: 'מחשבון משכנתה'!$C$7
Name LoanStart2: 'מחשבון משכנתה'!$G$7
Name LoanStart3: 'מחשבון משכנתה'!$K$7
Name LoanStart4: 'מחשבון משכנתה'!$O$7
Name MonthlyLoanPayment: 'מחשבון משכנתה'!$E$4
Name MonthlyLoanPayment2: 'מחשבון משכנתה'!$I$4
Name MonthlyLoanPayment3: 'מחשבון משכנתה'!$M$4
Name MonthlyLoanPayment4: 'מחשבון משכנתה'!$Q$4
Name NoPaymentsRemaining: ' טבלת סילוקין - מסכמת'!$J$4:$J$363
Name NoPaymentsRemaining: ' טבלת סילוקין - לפי מסלולים'!$J$4:$J$363
Name NoPaymentsRemaining2: #REF!
Name NoPaymentsRemaining2: הפחתה5[תשלומים שנותרו]
Name NoPaymentsRemaining2: הפחתה5[תשלומים שנותרו]
Name NoPaymentsRemaining3: #REF!
Name NoPaymentsRemaining3: הפחתה7[תשלומים שנותרו]
Name NoPaymentsRemaining3: הפחתה7[תשלומים שנותרו]
Name NoPaymentsRemaining4: #REF!
Name NoPaymentsRemaining4: הפחתה8[תשלומים שנותרו]
Name NoPaymentsRemaining4: הפחתה8[תשלומים שנותרו]
Name PaymentDurationIncreaseDecrease: INT(NPER(שיעור_ריבית/12,-[0]!MonthlyLoanPayment*VLOOKUP(PaymentPercentage,PaymentScenarios,2,FALSE),סכום_הלוואה))
Name PaymentDurationIncreaseDecrease: INT(NPER([0]!שיעור_ריבית/12,-[0]!MonthlyLoanPayment*VLOOKUP(PaymentPercentage,PaymentScenarios,2,FALSE),[0]!סכום_הלוואה))
Name PaymentDurationIncreaseDecrease: INT(NPER(שיעור_ריבית/12,-MonthlyLoanPayment*VLOOKUP(PaymentPercentage,PaymentScenarios,2,FALSE),סכום_הלוואה))
Name PercentageIncreaseDecrease: 1-' טבלת סילוקין - מסכמת'!PaymentDurationIncreaseDecrease/תקופת_ההלוואה
Name PercentageIncreaseDecrease: 1-דאשבורד!PaymentDurationIncreaseDecrease/[0]!תקופת_ההלוואה
Name PercentageIncreaseDecrease: 1-PaymentDurationIncreaseDecrease/תקופת_ההלוואה
Name PropertyTaxAmount: דאשבורד!$E$8
Name PropertyTaxAmount: 'מחשבון משכנתה'!$E$8
Name TitleRegion1..C8: דאשבורד!$B$3
Name TitleRegion1..C8: 'מחשבון משכנתה'!$B$3
Name TitleRegion2..E8: דאשבורד!$D$3
Name TitleRegion2..E8: 'מחשבון משכנתה'!$D$3
Name total_interest_paid: 'מחשבון משכנתה'!$E$7
Name total_interest_paid2: 'מחשבון משכנתה'!$I$7
Name total_interest_paid3: 'מחשבון משכנתה'!$M$7
Name total_interest_paid4: 'מחשבון משכנתה'!$Q$7
Name total_loan_payment: ' טבלת סילוקין - מסכמת'!$E$4:$F$363
Name total_loan_payment: ' טבלת סילוקין - לפי מסלולים'!$E$4:$F$363

Sheet דאשבורד
G1: מחשבון כדאיות
B2: ריכוז ההלוואה | G2: משך ההשקעה בחודשים | H2: 18 | I2: =H2/12 -> 1.5 | J2: כמה ריבית אשלם לתקופה | K2: כמה קרן אחזיר בתקופה | L2: מדד | M2: כמה שכ"ד אקבל | N2: תזרים עסקה כולל | O2: תזרים בניכוי הוצאות מימון וב.צ.מ | P2: עליית ערך
B3: פרטי הלוואה | C3: ערכים | D3: פירוט | E3: סה"כ | G3: שכ"ד חודשי | H3: 4000 | J3: {=_xlfn.IFS(H2=12,נתונים!C2,H2=18,נתונים!C3,H2=24,נתונים!C4,H2=36,נתונים!C5,H2=48,נתונים!C6,H2=60,נתונים!C7,H2=72,נתונים!C8,H2=84,נתונים!C9,H2=96,נתונים!C10,H2=108,נתונים!C11,H2=120,נתונים!C12)} -> 71388.181 | K3: {=_xlfn.IFS(H2=12,נתונים!D1,H2=18,נתונים!D2,H2=24,נתונים!D3,H2=36,נתונים!D4,H2=48,נתונים!D5,H2=60,נתונים!D6,H2=72,נתונים!D7,H2=84,נתונים!D8,H2=96,נתונים!D9,H2=108,נתונים!D10,H2=120,נתונים!D11)} -> 17864.991 | L3: {=_xlfn.IFS(H2=12,נתונים!E1,H2=18,נתונים!E2,H2=24,נתונים!E3,H2=36,נתונים!E4,H2=48,נתונים!E5,H2=60,נתונים!E6,H2=72,נתונים!E7,H2=84,נתונים!E8,H2=96,נתונים!E9,H2=108,נתונים!E10,H2=120,נתונים!E11)} -> 1990.7912 | M3: =H3*H2 -> 72000 | N3: =M3-(J3+K3+L3) -> -19243.963 | O3: =M3-J3-((H3)*I2)-K3-L3 -> -25243.963 | P3: =H5*H7*(H2/12) -> 143850
B4: ריבית חזויה | C4: =((סכום_הלוואה/C6)*שיעור_ריבית)+((סכום_הלוואה2/C6)*שיעור_ריבית2)+((סכום_הלוואה3/C6)*שיעור_ריבית3)+((סכום_הלוואה4/C6)*שיעור_ריבית4) -> 0.0482 | D4: תשלומי הלוואה חודשיים | E4: {=MonthlyLoanPayment+MonthlyLoanPayment2+MonthlyLoanPayment3+MonthlyLoanPayment4} -> 5472.1749 | G4: הון עצמי מושקע | H4: 370000 | J4: תשואה כוללת לעסקה | K4: תשואה כוללת על הון עצמי | L4: רווח נטו בש"ח | P4: מחיר מכירה צפוי
B5: תקופת ההלוואה (בחודשים) | C5: =MAX(תקופת_ההלוואה,תקופת_ההלוואה2,תקופת_ההלוואה3,תקופת_ההלוואה4) -> 360 | D5: סך התשלומים החודשיים* | E5: =פרטי_הלוואה[[#This Row],[סה"כ]]+פרטי_הלוואה2[[#This Row],[סה"כ]]+פרטי_הלוואה3[[#This Row],[סה"כ]]+פרטי_הלוואה4[[#This Row],[סה"כ]] -> 1909726.3 | G5: עלות נכס | H5: 1370000 | J5: =(L5) / (H5+H6) -> 0.065353068 | K5: =(L5)/(H4+H6) -> 0.22318861 | L5: =P5-((H5-K3)+H6)+O3 -> 92413.028 | P5: =H5+P3 -> 1513850
B6: סכום הלוואה | C6: {=הלוואה_כוללת} -> 1000000 | D6: סך תשלומי ההלוואה | E6: =פרטי_הלוואה[[#This Row],[סה"כ]]+פרטי_הלוואה2[[#This Row],[סה"כ]]+פרטי_הלוואה3[[#This Row],[סה"כ]]+פרטי_הלוואה4[[#This Row],[סה"כ]] -> 1876786.6 | G6: עלויות נלוות (מס,ליווי,עו"ד,תיווך) | H6: =(H5*0.02)*1.17+ 6000 + 6000 -> 44058 | J6: תשואה שנתית כוללת | K6: תשואה שנתית על הון עצמי | L6: רווח שנתי נטו בש"ח
B7: תאריך תחילת ההלוואה | C7: =MIN(LoanStart,LoanStart2,LoanStart3,LoanStart4) -> 45383 | D7: סך הריבית ששולמה | E7: {=total_interest_paid+total_interest_paid2+total_interest_paid3+total_interest_paid4} -> 843848.04 | G7: עליית ערך ממוצעת לשנה | H7: 0.07 | J7: =J5/I2 -> 0.043568712 | K7: =K5/I2 -> 0.1487924 | L7: =L5/I2 -> 61608.685
E8: 0 | G8: מחיר מכירה צפוי | H8: =H5*((1+H7)^I2) -> 1516338.8
B9: מדד | C9: =(מדד+מדד2+מדד3+מדד4)/4 -> 0.005 | D9: סך תשלומי הצמדה | E9: =פרטי_הלוואה[[#This Row],[סה"כ]]+פרטי_הלוואה2[[#This Row],[סה"כ]]+פרטי_הלוואה3[[#This Row],[סה"כ]]+פרטי_הלוואה4[[#This Row],[סה"כ]] -> 32939.727 | G9: מחיר מכירה צפוי | H9: =H5*((1+H7)^I2) -> 1516338.8 | J9: תחילת השקעה | K9: סיום השקעה
B10: עלות לשקל | C10: =E6/C6 -> 1.8767866 | D10: תשלום הלוואה חודשי | E10: =E4 -> 5472.1749 | G10: רווח (בהנחת ריבית דריבית) | H10: =H8-H5 -> 146338.75 | J10: 44682 | K10: =J10+(I2*365) -> 45229.5
E11: לטבלת הסילוקין
B13: =B6 -> סכום הלוואה | C13: =D7 -> סך הריבית ששולמה | D13: =D9 -> סך תשלומי הצמדה
B14: =C6 -> 1000000 | C14: =E7 -> 843848.04 | D14: =E9 -> 32939.727

Sheet מחשבון משכנתה
B1: מסלול 1 | F1: מסלול 2 | J1: מסלול 3 | N1: מסלול 4
B2: פריים | F2: קל"צ | J2: קבועה צמודה
B3: פרטי הלוואה | C3: ערכים | D3: פירוט | E3: סה"כ | F3: פרטי הלוואה | G3: ערכים | H3: פירוט | I3: סה"כ | J3: פרטי הלוואה | K3: ערכים | L3: פירוט | M3: סה"כ | N3: פרטי הלוואה | O3: ערכים | P3: פירוט | Q3: סה"כ
B4: שיעור ריבית | C4: 0.053 | D4: תשלומי הלוואה חודשיים | E4: =IFERROR(PMT(שיעור_ריבית/12,תקופת_ההלוואה,-סכום_הלוואה),0) -> 3331.8279 | F4: שיעור ריבית | G4: 0.047 | H4: תשלומי הלוואה חודשיים | I4: =IFERROR(PMT(שיעור_ריבית2/12,תקופת_ההלוואה2,-סכום_הלוואה2),0) -> 1701.7358 | J4: שיעור ריבית | K4: 0.023 | L4: תשלומי הלוואה חודשיים | M4: =IFERROR(PMT(שיעור_ריבית3/12,תקופת_ההלוואה3,-סכום_הלוואה3),0) -> 438.61118 | N4: שיעור ריבית | O4: 0 | P4: תשלומי הלוואה חודשיים | Q4: =IFERROR(PMT(שיעור_ריבית4/12,תקופת_ההלוואה4,-סכום_הלוואה4),0) -> 0
B5: תקופת ההלוואה (בחודשים) | C5: 360 | D5: סך התשלומים החודשיים* | E5: =IFERROR(IF(ValuesEntered,SUM(total_payments),0),0) -> 1196811.1 | F5: תקופת ההלוואה (בחודשים) | G5: 300 | H5: סך התשלומים החודשיים* | I5: =IFERROR(IF(ValuesEntered2,SUM(total_payments2),0),0) -> 509347.81 | J5: תקופת ההלוואה (בחודשים) | K5: 300 | L5: סך התשלומים החודשיים* | M5: =IFERROR(IF(ValuesEntered3,SUM(total_payments3),0),0) -> 203567.42 | N5: תקופת ההלוואה (בחודשים) | O5: 1 | P5: סך התשלומים החודשיים* | Q5: =IFERROR(IF(ValuesEntered4,SUM(total_payments4),0),0) -> 0
B6: סכום הלוואה | C6: 600000 | D6: סך תשלומי ההלוואה | E6: =IFERROR(IF(ValuesEntered,SUM(total_loan_payment),0),0) -> 1196811.1 | F6: סכום הלוואה | G6: 300000 | H6: סך תשלומי ההלוואה | I6: =IFERROR(IF(ValuesEntered2,SUM(total_loan_payment2),0),0) -> 509347.81 | J6: סכום הלוואה | K6: 100000 | L6: סך תשלומי ההלוואה | M6: =IFERROR(IF(ValuesEntered3,SUM(total_loan_payment3),0),0) -> 170627.69 | N6: סכום הלוואה | O6: 0 | P6: סך תשלומי ההלוואה | Q6: =IFERROR(IF(ValuesEntered4,SUM(total_loan_payment4),0),0) -> 0
B7: תאריך תחילת ההלוואה | C7: 45383 | D7: סך הריבית ששולמה | E7: =IFERROR(IF(ValuesEntered,SUM(ריבית),0),0) -> 596811.06 | F7: תאריך תחילת ההלוואה | G7: 45383 | H7: סך הריבית ששולמה | I7: =IFERROR(IF(ValuesEntered2,SUM(ריבית2),0),0) -> 209347.81 | J7: תאריך תחילת ההלוואה | K7: =TODAY()+120 -> 45621 | L7: סך הריבית ששולמה | M7: =IFERROR(IF(ValuesEntered3,SUM(ריבית3),0),0) -> 37689.174 | N7: תאריך תחילת ההלוואה | O7: =TODAY()+120 -> 45621 | P7: סך הריבית ששולמה | Q7: =IFERROR(IF(ValuesEntered4,SUM(ריבית4),0),0) -> 0
B8: מדד | C8: 0.01 | D8: סך תשלומי הצמדה | E8: 0 | F8: מדד | G8: 0.01 | H8: סך תשלומי הצמדה | I8: 0 | J8: מדד | K8: 0.01 | L8: סך תשלומי הצמדה | M8: 0 | N8: מדד | O8: 0.01 | P8: סך תשלומי הצמדה | Q8: 0
B9: מדד | C9: 0 | D9: סך תשלומי הצמדה | E9: =SUM(הפחתה[מדד]) -> 0 | F9: מדד | G9: 0 | H9: סך תשלומי הצמדה | I9: =SUM(הפחתה5[מדד]) -> 0 | J9: מדד | K9: 0.02 | L9: סך תשלומי הצמדה | M9: =SUM(הפחתה7[מדד]) -> 32939.727 | N9: מדד | O9: 0 | P9: סך תשלומי הצמדה | Q9: =SUM(הפחתה8[מדד]) -> 0
D10: תשלום הלוואה חודשי | E10: =E4 -> 3331.8279 | H10: תשלום הלוואה חודשי | I10: =I4 -> 1701.7358 | L10: תשלום הלוואה חודשי | M10: =M4 -> 438.61118 | P10: תשלום הלוואה חודשי | Q10: =Q4 -> 0
B11: יש להזין כאן את הסלול בעל המשך הארוך ביותר | E11: לטבלת הסילוקין | I11: לטבלת הסילוקין | M11: לטבלת הסילוקין | Q11: לטבלת הסילוקין
B13: סה"כ הלוואה מקורית | C13: =סכום_הלוואה+סכום_הלוואה2+סכום_הלוואה3+סכום_הלוואה4 -> 1000000 | D13: סך הלוואה חדשה | G13: 1 | H13: בחרו את המסלול ממנו תרצו לסלק והפחיתו ממנו את הסכום הרצוי ע"י שינוי סכום ההלוואה. בנוסף, רשמו את הסכום אותו תרצו לסלק בטבלה הקטנה מטה במקום המתאים "סך תשלום לסילוק" במשבצת הצהובה.
B14: תשלום חדשי מקורי | C14: =E10+I10+M10+Q10 -> 5472.1749 | D14: תשלום חודשי חדש | G14: 2 | H14: לאחר הפחתת הסכום הרצוי - רשמו ב"סך הלוואה חדשה","תשלום חודשי חדש" ו"תשלום ריבית כולל חדש להלוואה" את הסכומים החדשים שיצאו. ניתן לראותם בטבלה הקטנה מטה.את הסכומים החדשים שמופיעים בטבלה הקטנה מטה.
B15: תשלום ריבית כולל מקורי להלוואה | C15: =total_interest_paid+total_interest_paid2+total_interest_paid3+total_interest_paid4 -> 843848.04 | D15: תשלום ריבית כולל חדש להלוואה | G15: 3 | H15: לאחר שכתבתם את הסכומים החדשים במשבצות הצהובות החזירו את סכום ההלוואה לערכו המקורי לפני ההפחתה.
B16: סך תשלום לסילוק | D16: הפרש תשלום חודשי | E16: =C14-E14 -> 5472.1749 | G16: 4 | H16: כעת - תוכלו לראות את הפרש התשלום החודשי שהתקבל בעקבות הסילוק, את הריבית שנחסכה ואת התשואה השנתית שהשגתם עבור הכסף בהסתכלות תזרימית או בחישוב חסכון הריבית
B17: תשואה שנתית תזרימית | C17: =(E16*12)/C16 -> #DIV/0! | D17: סך ריבית שנחסכה | E17: =C15-E15 -> 843848.04 | G17: 5 | H17: צפו בדוגמה שצירפנו עבורכם!

Sheet  טבלת סילוקין - מסכמת
B1: טבלת סילוקין
B2: מסכמת
B3: מס' | C3: תאריך | D3: יתרת פתיחה | E3: ריבית | F3: קרן | G3: מס רכוש | H3: סך החזר | I3: יתרת סגירה | J3: תשלומים שנותרו
B4: =MAX(הפחתה[[#This Row],[מס'']],הפחתה5[[#This Row],[מס'']],הפחתה7[[#This Row],[מס'']],הפחתה8[[#This Row],[מס'']]) -> 1 | C4: =IF(ValuesEntered,IF(הפחתה23[[#This Row],[מס'']]<=תקופת_ההלוואה,IF(ROW()-ROW(הפחתה[[#Headers],[תאריך]])=1,LoanStart,IF(I3>0,EDATE(C3,1),"")),""),"") -> 45383 | D4: =SUM(הפחתה[[#This Row],[יתרת פתיחה]],הפחתה5[[#This Row],[יתרת פתיחה]],הפחתה7[[#This Row],[יתרת פתיחה]],הפחתה8[[#This Row],[יתרת פתיחה]]) -> 1000000 | E4: =SUM(הפחתה[[#This Row],[ריבית]],הפחתה5[[#This Row],[ריבית]],הפחתה7[[#This Row],[ריבית]],הפחתה8[[#This Row],[ריבית]]) -> 4016.6667 | F4: =SUM(הפחתה[[#This Row],[קרן]],הפחתה5[[#This Row],[קרן]],הפחתה7[[#This Row],[קרן]],הפחתה8[[#This Row],[קרן]]) -> 1455.5082 | G4: =IF(הפחתה23[[#This Row],[תאריך]]="",0,PropertyTaxAmount) -> 0 | H4: =IF(הפחתה23[[#This Row],[תאריך]]="",0,הפחתה23[[#This Row],[ריבית]]+הפחתה23[[#This Row],[קרן]]+הפחתה23[[#This Row],[מס רכוש]]) -> 5472.1749 | I4: =IF(הפחתה23[[#This Row],[תאריך]]="",0,הפחתה23[[#This Row],[יתרת פתיחה]]-הפחתה23[[#This Row],[קרן]]) -> 998544.49 | J4: =MAX(הפחתה[[#This Row],[תשלומים שנותרו]],הפחתה5[[#This Row],[תשלומים שנותרו]],הפחתה7[[#This Row],[תשלומים שנותרו]],הפחתה8[[#This Row],[תשלומים שנותרו]]) -> 359
B5: =MAX(הפחתה[[#This Row],[מס'']],הפחתה5[[#This Row],[מס'']],הפחתה7[[#This Row],[מס'']],הפחתה8[[#This Row],[מס'']]) -> 2 | C5: =IF(ValuesEntered,IF(הפחתה23[[#This Row],[מס'']]<=תקופת_ההלוואה,IF(ROW()-ROW(הפחתה[[#Headers],[תאריך]])=1,LoanStart,IF(I4>0,EDATE(C4,1),"")),""),"") -> 45413 | D5: =SUM(הפחתה[[#This Row],[יתרת פתיחה]],הפחתה5[[#This Row],[יתרת פתיחה]],הפחתה7[[#This Row],[יתרת פתיחה]],הפחתה8[[#This Row],[יתרת פתיחה]]) -> 998711.16 | E5: =SUM(הפחתה[[#This Row],[ריבית]],הפחתה5[[#This Row],[ריבית]],הפחתה7[[#This Row],[ריבית]],הפחתה8[[#This Row],[ריבית]]) -> 4006.1867 | F5: =SUM(הפחתה[[#This Row],[קרן]],הפחתה5[[#This Row],[קרן]],הפחתה7[[#This Row],[קרן]],הפחתה8[[#This Row],[קרן]]) -> 1461.4694 | G5: =IF(הפחתה23[[#This Row],[תאריך]]="",0,PropertyTaxAmount) -> 0 | H5: =IF(הפחתה23[[#This Row],[תאריך]]="",0,הפחתה23[[#This Row],[ריבית]]+הפחתה23[[#This Row],[קרן]]+הפחתה23[[#This Row],[מס רכוש]]) -> 5467.6561 | I5: =IF(הפחתה23[[#This Row],[תאריך]]="",0,הפחתה23[[#This Row],[יתרת פתיחה]]-הפחתה23[[#This Row],[קרן]]) -> 997249.69 | J5: =MAX(הפחתה[[#This Row],[תשלומים שנותרו]],הפחתה5[[#This Row],[תשלומים שנותרו]],הפחתה7[[#This Row],[תשלומים שנותרו]],הפחתה8[[#This Row],[תשלומים שנותרו]]) -> 358
B6: =MAX(הפחתה[[#This Row],[מס'']],הפחתה5[[#This Row],[מס'']],הפחתה7[[#This Row],[מס'']],הפחתה8[[#This Row],[מס'']]) -> 3 | C6: =IF(ValuesEntered,IF(הפחתה23[[#This Row],[מס'']]<=תקופת_ההלוואה,IF(ROW()-ROW(הפחתה[[#Headers],[תאריך]])=1,LoanStart,IF(I5>0,EDATE(C5,1),"")),""),"") -> 45444 | D6: =SUM(הפחתה[[#This Row],[יתרת פתיחה]],הפחתה5[[#This Row],[יתרת פתיחה]],הפחתה7[[#This Row],[יתרת פתיחה]],הפחתה8[[#This Row],[יתרת פתיחה]]) -> 997416.22 | E6: =SUM(הפחתה[[#This Row],[ריבית]],הפחתה5[[#This Row],[ריבית]],הפחתה7[[#This Row],[ריבית]],הפחתה8[[#This Row],[ריבית]]) -> 4000.9116 | F6: =SUM(הפחתה[[#This Row],[קרן]],הפחתה5[[#This Row],[קרן]],הפחתה7[[#This Row],[קרן]],הפחתה8[[#This Row],[קרן]]) -> 1467.4551 | G6: =IF(הפחתה23[[#This Row],[תאריך]]="",0,PropertyTaxAmount) -> 0 | H6: =IF(הפחתה23[[#This Row],[תאריך]]="",0,הפחתה23[[#This Row],[ריבית]]+הפחתה23[[#This Row],[קרן]]+הפחתה23[[#This Row],[מס רכוש]]) -> 5468.3667 | I6: =IF(הפחתה23[[#This Row],[תאריך]]="",0,הפחתה23[[#This Row],[יתרת פתיחה]]-הפחתה23[[#This Row],[קרן]]) -> 995948.77 | J6: =MAX(הפחתה[[#This Row],[תשלומים שנותרו]],הפחתה5[[#This Row],[תשלומים שנותרו]],הפחתה7[[#This Row],[תשלומים שנותרו]],הפחתה8[[#This Row],[תשלומים שנותרו]]) -> 357
B7: =MAX(הפחתה[[#This Row],[מס'']],הפחתה5[[#This Row],[מס'']],הפחתה7[[#This Row],[מס'']],הפחתה8[[#This Row],[מס'']]) -> 4 | C7: =IF(ValuesEntered,IF(הפחתה23[[#This Row],[מס'']]<=תקופת_ההלוואה,IF(ROW()-ROW(הפחתה[[#Headers],[תאריך]])=1,LoanStart,IF(I6>0,EDATE(C6,1),"")),""),"") -> 45474 | D7: =SUM(הפחתה[[#This Row],[יתרת פתיחה]],הפחתה5[[#This Row],[יתרת פתיחה]],הפחתה7[[#This Row],[יתרת פתיחה]],הפחתה8[[#This Row],[יתרת פתיחה]]) -> 996115.16 | E7: =SUM(הפחתה[[#This Row],[ריבית]],הפחתה5[[#This Row],[ריבית]],הפחתה7[[#This Row],[ריבית]],הפחתה8[[#This Row],[ריבית]]) -> 3995.613 | F7: =SUM(הפחתה[[#This Row],[קרן]],הפחתה5[[#This Row],[קרן]],הפחתה7[[#This Row],[קרן]],הפחתה8[[#This Row],[קרן]]) -> 1473.4655 | G7: =IF(הפחתה23[[#This Row],[תאריך]]="",0,PropertyTaxAmount) -> 0 | H7: =IF(הפחתה23[[#This Row],[תאריך]]="",0,הפחתה23[[#This Row],[ריבית]]+הפחתה23[[#This Row],[קרן]]+הפחתה23[[#This Row],[מס רכוש]]) -> 5469.0785 | I7: =IF(הפחתה23[[#This Row],[תאריך]]="",0,הפחתה23[[#This Row],[יתרת פתיחה]]-הפחתה23[[#This Row],[קרן]]) -> 994641.7 | J7: =MAX(הפחתה[[#This Row],[תשלומים שנותרו]],הפחתה5[[#This Row],[תשלומים שנותרו]],הפחתה7[[#This Row],[תשלומים שנותרו]],הפחתה8[[#This Row],[תשלומים שנותרו]]) -> 356
B8: =MAX(הפחתה[[#This Row],[מס'']],הפחתה5[[#This Row],[מס'']],הפחתה7[[#This Row],[מס'']],הפחתה8[[#This Row],[מס'']]) -> 5 | C8: =IF(ValuesEntered,IF(הפחתה23[[#This Row],[מס'']]<=תקופת_ההלוואה,IF(ROW()-ROW(הפחתה[[#Headers],[תאריך]])=1,LoanStart,IF(I7>0,EDATE(C7,1),"")),""),"") -> 45505 | D8: =SUM(הפחתה[[#This Row],[יתרת פתיחה]],הפחתה5[[#This Row],[יתרת פתיחה]],הפחתה7[[#This Row],[יתרת פתיחה]],הפחתה8[[#This Row],[יתרת פתיחה]]) -> 994807.96 | E8: =SUM(הפחתה[[#This Row],[ריבית]],הפחתה5[[#This Row],[ריבית]],הפחתה7[[#This Row],[ריבית]],הפחתה8[[#This Row],[ריבית]]) -> 3990.2907 | F8: =SUM(הפחתה[[#This Row],[קרן]],הפחתה5[[#This Row],[קרן]],הפחתה7[[#This Row],[קרן]],הפחתה8[[#This Row],[קרן]]) -> 1479.5007 | G8: =IF(הפחתה23[[#This Row],[תאריך]]="",0,PropertyTaxAmount) -> 0 | H8: =IF(הפחתה23[[#This Row],[תאריך]]="",0,הפחתה23[[#This Row],[ריבית]]+הפחתה23[[#This Row],[קרן]]+הפחתה23[[#This Row],[מס רכוש]]) -> 5469.7914 | I8: =IF(הפחתה23[[#This Row],[תאריך]]="",0,הפחתה23[[#This Row],[יתרת פתיחה]]-הפחתה23[[#This Row],[קרן]]) -> 993328.46 | J8: =MAX(הפחתה[[#This Row],[תשלומים שנותרו]],הפחתה5[[#This Row],[תשלומים שנותרו]],הפחתה7[[#This Row],[תשלומים שנותרו]],הפחתה8[[#This Row],[תשלומים שנותרו]]) -> 355
B9: =MAX(הפחתה[[#This Row],[מס'']],הפחתה5[[#This Row],[מס'']],הפחתה7[[#This Row],[מס'']],הפחתה8[[#This Row],[מס'']]) -> 6 | C9: =IF(ValuesEntered,IF(הפחתה23[[#This Row],[מס'']]<=תקופת_ההלוואה,IF(ROW()-ROW(הפחתה[[#Headers],[תאריך]])=1,LoanStart,IF(I8>0,EDATE(C8,1),"")),""),"") -> 45536 | D9: =SUM(הפחתה[[#This Row],[יתרת פתיחה]],הפחתה5[[#This Row],[יתרת פתיחה]],הפחתה7[[#This Row],[יתרת פתיחה]],הפחתה8[[#This Row],[יתרת פתיחה]]) -> 993494.58 | E9: =SUM(הפחתה[[#This Row],[ריבית]],הפחתה5[[#This Row],[ריבית]],הפחתה7[[#This Row],[ריבית]],הפחתה8[[#This Row],[ריבית]]) -> 3984.9447 | F9: =SUM(הפחתה[[#This Row],[קרן]],הפחתה5[[#This Row],[קרן]],הפחתה7[[#This Row],[קרן]],הפחתה8[[#This Row],[קרן]]) -> 1485.5607 | G9: =IF(הפחתה23[[#This Row],[תאריך]]="",0,PropertyTaxAmount) -> 0 | H9: =IF(הפחתה23[[#This Row],[תאריך]]="",0,הפחתה23[[#This Row],[ריבית]]+הפחתה23[[#This Row],[קרן]]+הפחתה23[[#This Row],[מס רכוש]]) -> 5470.5054 | I9: =IF(הפחתה23[[#This Row],[תאריך]]="",0,הפחתה23[[#This Row],[יתרת פתיחה]]-הפחתה23[[#This Row],[קרן]]) -> 992009.02 | J9: =MAX(הפחתה[[#This Row],[תשלומים שנותרו]],הפחתה5[[#This Row],[תשלומים שנותרו]],הפחתה7[[#This Row],[תשלומים שנותרו]],הפחתה8[[#This Row],[תשלומים שנותרו]]) -> 354
B10: =MAX(הפחתה[[#This Row],[מס'']],הפחתה5[[#This Row],[מס'']],הפחתה7[[#This Row],[מס'']],הפחתה8[[#This Row],[מס'']]) -> 7 | C10: =IF(ValuesEntered,IF(הפחתה23[[#This Row],[מס'']]<=תקופת_ההלוואה,IF(ROW()-ROW(הפחתה[[#Headers],[תאריך]])=1,LoanStart,IF(I9>0,EDATE(C9,1),"")),""),"") -> 45566 | D10: =SUM(הפחתה[[#This Row],[יתרת פתיחה]],הפחתה5[[#This Row],[יתרת פתיחה]],הפחתה7[[#This Row],[יתרת פתיחה]],הפחתה8[[#This Row],[יתרת פתיחה]]) -> 992175 | E10: =SUM(הפחתה[[#This Row],[ריבית]],הפחתה5[[#This Row],[ריבית]],הפחתה7[[#This Row],[ריבית]],הפחתה8[[#This Row],[ריבית]]) -> 3979.5748 | F10: =SUM(הפחתה[[#This Row],[קרן]],הפחתה5[[#This Row],[קרן]],הפחתה7[[#This Row],[קרן]],הפחתה8[[#This Row],[קרן]]) -> 1491.6457 | G10: =IF(הפחתה23[[#This Row],[תאריך]]="",0,PropertyTaxAmount) -> 0 | H10: =IF(הפחתה23[[#This Row],[תאריך]]="",0,הפחתה23[[#This Row],[ריבית]]+הפחתה23[[#This Row],[קרן]]+הפחתה23[[#This Row],[מס רכוש]]) -> 5471.2206 | I10: =IF(הפחתה23[[#This Row],[תאריך]]="",0,הפחתה23[[#This Row],[יתרת פתיחה]]-הפחתה23[[#This Row],[קרן]]) -> 990683.35 | J10: =MAX(הפחתה[[#This Row],[תשלומים שנותרו]],הפחתה5[[#This Row],[תשלומים שנותרו]],הפחתה7[[#This Row],[תשלומים שנותרו]],הפחתה8[[#This Row],[תשלומים שנותרו]]) -> 353
B11: =MAX(הפחתה[[#This Row],[מס'']],הפחתה5[[#This Row],[מס'']],הפחתה7[[#This Row],[מס'']],הפחתה8[[#This Row],[מס'']]) -> 8 | C11: =IF(ValuesEntered,IF(הפחתה23[[#This Row],[מס'']]<=תקופת_ההלוואה,IF(ROW()-ROW(הפחתה[[#Headers],[תאריך]])=1,LoanStart,IF(I10>0,EDATE(C10,1),"")),""),"") -> 45597 | D11: =SUM(הפחתה[[#This Row],[יתרת פתיחה]],הפחתה5[[#This Row],[יתרת פתיחה]],הפחתה7[[#This Row],[יתרת פתיחה]],הפחתה8[[#This Row],[יתרת פתיחה]]) -> 990849.19 | E11: =SUM(הפחתה[[#This Row],[ריבית]],הפחתה5[[#This Row],[ריבית]],הפחתה7[[#This Row],[ריבית]],הפחתה8[[#This Row],[ריבית]]) -> 3974.1811 | F11: =SUM(הפחתה[[#This Row],[קרן]],הפחתה5[[#This Row],[קרן]],הפחתה7[[#This Row],[קרן]],הפחתה8[[#This Row],[קרן]]) -> 1497.7558 | G11: =IF(הפחתה23[[#This Row],[תאריך]]="",0,PropertyTaxAmount) -> 0 | H11: =IF(הפחתה23[[#This Row],[תאריך]]="",0,הפחתה23[[#This Row],[ריבית]]+הפחתה23[[#This Row],[קרן]]+הפחתה23[[#This Row],[מס רכוש]]) -> 5471.9369 | I11: =IF(הפחתה23[[#This Row],[תאריך]]="",0,הפחתה23[[#This Row],[יתרת פתיחה]]-הפחתה23[[#This Row],[קרן]]) -> 989351.44 | J11: =MAX(הפחתה[[#This Row],[תשלומים שנותרו]],הפחתה5[[#This Row],[תשלומים שנותרו]],הפחתה7[[#This Row],[תשלומים שנותרו]],הפחתה8[[#This Row],[תשלומים שנותרו]]) -> 352
B12: =MAX(הפחתה[[#This Row],[מס'']],הפחתה5[[#This Row],[מס'']],הפחתה7[[#This Row],[מס'']],הפחתה8[[#This Row],[מס'']]) -> 9 | C12: =IF(ValuesEntered,IF(הפחתה23[[#This Row],[מס'']]<=תקופת_ההלוואה,IF(ROW()-ROW(הפחתה[[#Headers],[תאריך]])=1,LoanStart,IF(I11>0,EDATE(C11,1),"")),""),"") -> 45627 | D12: =SUM(הפחתה[[#This Row],[יתרת פתיחה]],הפחתה5[[#This Row],[יתרת פתיחה]],הפחתה7[[#This Row],[יתרת פתיחה]],הפחתה8[[#This Row],[יתרת פתיחה]]) -> 989517.13 | E12: =SUM(הפחתה[[#This Row],[ריבית]],הפחתה5[[#This Row],[ריבית]],הפחתה7[[#This Row],[ריבית]],הפחתה8[[#This Row],[ריבית]]) -> 3968.7632 | F12: =SUM(הפחתה[[#This Row],[קרן]],הפחתה5[[#This Row],[קרן]],הפחתה7[[#This Row],[קרן]],הפחתה8[[#This Row],[קרן]]) -> 1503.8911 | G12: =IF(הפחתה23[[#This Row],[תאריך]]="",0,PropertyTaxAmount) -> 0 | H12: =IF(הפחתה23[[#This Row],[תאריך]]="",0,הפחתה23[[#This Row],[ריבית]]+הפחתה23[[#This Row],[קרן]]+הפחתה23[[#This Row],[מס רכוש]]) -> 5472.6543 | I12: =IF(הפחתה23[[#This Row],[תאריך]]="",0,הפחתה23[[#This Row],[יתרת פתיחה]]-הפחתה23[[#This Row],[קרן]]) -> 988013.24 | J12: =MAX(הפחתה[[#This Row],[תשלומים שנותרו]],הפחתה5[[#This Row],[תשלומים שנותרו]],הפחתה7[[#This Row],[תשלומים שנותרו]],הפחתה8[[#This Row],[תשלומים שנותרו]]) -> 351
B13: =MAX(הפחתה[[#This Row],[מס'']],הפחתה5[[#This Row],[מס'']],הפחתה7[[#This Row],[מס'']],הפחתה8[[#This Row],[מס'']]) -> 10 | C13: =IF(ValuesEntered,IF(הפחתה23[[#This Row],[מס'']]<=תקופת_ההלוואה,IF(ROW()-ROW(הפחתה[[#Headers],[תאריך]])=1,LoanStart,IF(I12>0,EDATE(C12,1),"")),""),"") -> 45658 | D13: =SUM(הפחתה[[#This Row],[יתרת פתיחה]],הפחתה5[[#This Row],[יתרת פתיחה]],הפחתה7[[#This Row],[יתרת פתיחה]],הפחתה8[[#This Row],[יתרת פתיחה]]) -> 988178.79 | E13: =SUM(הפחתה[[#This Row],[ריבית]],הפחתה5[[#This Row],[ריבית]],הפחתה7[[#This Row],[ריבית]],הפחתה8[[#This Row],[ריבית]]) -> 3963.3212 | F13: =SUM(הפחתה[[#This Row],[קרן]],הפחתה5[[#This Row],[קרן]],הפחתה7[[#This Row],[קרן]],הפחתה8[[#This Row],[קרן]]) -> 1510.0517 | G13: =IF(הפחתה23[[#This Row],[תאריך]]="",0,PropertyTaxAmount) -> 0 | H13: =IF(הפחתה23[[#This Row],[תאריך]]="",0,הפחתה23[[#This Row],[ריבית]]+הפחתה23[[#This Row],[קרן]]+הפחתה23[[#This Row],[מס רכוש]]) -> 5473.3729 | I13: =IF(הפחתה23[[#This Row],[תאריך]]="",0,הפחתה23[[#This Row],[יתרת פתיחה]]-הפחתה23[[#This Row],[קרן]]) -> 986668.74 | J13: =MAX(הפחתה[[#This Row],[תשלומים שנותרו]],הפחתה5[[#This Row],[תשלומים שנותרו]],הפחתה7[[#This Row],[תשלומים שנותרו]],הפחתה8[[#This Row],[תשלומים שנותרו]]) -> 350
B14: =MAX(הפחתה[[#This Row],[מס'']],הפחתה5[[#This Row],[מס'']],הפחתה7[[#This Row],[מס'']],הפחתה8[[#This Row],[מס'']]) -> 11 | C14: =IF(ValuesEntered,IF(הפחתה23[[#This Row],[מס'']]<=תקופת_ההלוואה,IF(ROW()-ROW(הפחתה[[#Headers],[תאריך]])=1,LoanStart,IF(I13>0,EDATE(C13,1),"")),""),"") -> 45689 | D14: =SUM(הפחתה[[#This Row],[יתרת פתיחה]],הפחתה5[[#This Row],[יתרת פתיחה]],הפחתה7[[#This Row],[יתרת פתיחה]],הפחתה8[[#This Row],[יתרת פתיחה]]) -> 986834.14 | E14: =SUM(הפחתה[[#This Row],[ריבית]],הפחתה5[[#This Row],[ריבית]],הפחתה7[[#This Row],[ריבית]],הפחתה8[[#This Row],[ריבית]]) -> 3957.855 | F14: =SUM(הפחתה[[#This Row],[קרן]],הפחתה5[[#This Row],[קרן]],הפחתה7[[#This Row],[קרן]],הפחתה8[[#This Row],[קרן]]) -> 1516.2377 | G14: =IF(הפחתה23[[#This Row],[תאריך]]="",0,PropertyTaxAmount) -> 0 | H14: =IF(הפחתה23[[#This Row],[תאריך]]="",0,הפחתה23[[#This Row],[ריבית]]+הפחתה23[[#This Row],[קרן]]+הפחתה23[[#This Row],[מס רכוש]]) -> 5474.0927 | I14: =IF(הפחתה23[[#This Row],[תאריך]]="",0,הפחתה23[[#This Row],[יתרת פתיחה]]-הפחתה23[[#This Row],[קרן]]) -> 985317.9 | J14: =MAX(הפחתה[[#This Row],[תשלומים שנותרו]],הפחתה5[[#This Row],[תשלומים שנותרו]],הפחתה7[[#This Row],[תשלומים שנותרו]],הפחתה8[[#This Row],[תשלומים שנותרו]]) -> 349
B15: =MAX(הפחתה[[#This Row],[מס'']],הפחתה5[[#This Row],[מס'']],הפחתה7[[#This Row],[מס'']],הפחתה8[[#This Row],[מס'']]) -> 12 | C15: =IF(ValuesEntered,IF(הפחתה23[[#This Row],[מס'']]<=תקופת_ההלוואה,IF(ROW()-ROW(הפחתה[[#Headers],[תאריך]])=1,LoanStart,IF(I14>0,EDATE(C14,1),"")),""),"") -> 45717 | D15: =SUM(הפחתה[[#This Row],[יתרת פתיחה]],הפחתה5[[#This Row],[יתרת פתיחה]],הפחתה7[[#This Row],[יתרת פתיחה]],הפחתה8[[#This Row],[יתרת פתיחה]]) -> 985483.15 | E15: =SUM(הפחתה[[#This Row],[ריבית]],הפחתה5[[#This Row],[ריבית]],הפחתה7[[#This Row],[ריבית]],הפחתה8[[#This Row],[ריבית]]) -> 3952.3644 | F15: =SUM(הפחתה[[#This Row],[קרן]],הפחתה5[[#This Row],[קרן]],הפחתה7[[#This Row],[קרן]],הפחתה8[[#This Row],[קרן]]) -> 1522.4491 | G15: =IF(הפחתה23[[#This Row],[תאריך]]="",0,PropertyTaxAmount) -> 0 | H15: =IF(הפחתה23[[#This Row],[תאריך]]="",0,הפחתה23[[#This Row],[ריבית]]+הפחתה23[[#This Row],[קרן]]+הפחתה23[[#This Row],[מס רכוש]]) -> 5474.8136 | I15: =IF(הפחתה23[[#This Row],[תאריך]]="",0,הפחתה23[[#This Row],[יתרת פתיחה]]-הפחתה23[[#This Row],[קרן]]) -> 983960.7 | J15: =MAX(הפחתה[[#This Row],[תשלומים שנותרו]],הפחתה5[[#This Row],[תשלומים שנותרו]],הפחתה7[[#This Row],[תשלומים שנותרו]],הפחתה8[[#This Row],[תשלומים שנותרו]]) -> 348
... B363: =MAX(הפחתה[[#This Row],[מס'']],הפחתה5[[#This Row],[מס'']],הפחתה7[[#This Row],[מס'']],הפחתה8[[#This Row],[מס'']]) -> 360 | C363: =IF(ValuesEntered,IF(הפחתה23[[#This Row],[מס'']]<=תקופת_ההלוואה,IF(ROW()-ROW(הפחתה[[#Headers],[תאריך]])=1,LoanStart,IF(I362>0,EDATE(C362,1),"")),""),"") -> 56309 | D363: =SUM(הפחתה[[#This Row],[יתרת פתיחה]],הפחתה5[[#This Row],[יתרת פתיחה]],הפחתה7[[#This Row],[יתרת פתיחה]],הפחתה8[[#This Row],[יתרת פתיחה]]) -> 3317.177 | E363: =SUM(הפחתה[[#This Row],[ריבית]],הפחתה5[[#This Row],[ריבית]],הפחתה7[[#This Row],[ריבית]],הפחתה8[[#This Row],[ריבית]]) -> 0 | F363: =SUM(הפחתה[[#This Row],[קרן]],הפחתה5[[#This Row],[קרן]],הפחתה7[[#This Row],[קרן]],הפחתה8[[#This Row],[קרן]]) -> 3317.177 | G363: =IF(הפחתה23[[#This Row],[תאריך]]="",0,PropertyTaxAmount) -> 0 | H363: =IF(הפחתה23[[#This Row],[תאריך]]="",0,הפחתה23[[#This Row],[ריבית]]+הפחתה23[[#This Row],[קרן]]+הפחתה23[[#This Row],[מס רכוש]]) -> 3317.177 | I363: =IF(הפחתה23[[#This Row],[תאריך]]="",0,הפחתה23[[#This Row],[יתרת פתיחה]]-הפחתה23[[#This Row],[קרן]]) -> -4.5474735e-13 | J363: =MAX(הפחתה[[#This Row],[תשלומים שנותרו]],הפחתה5[[#This Row],[תשלומים שנותרו]],הפחתה7[[#This Row],[תשלומים שנותרו]],הפחתה8[[#This Row],[תשלומים שנותרו]]) -> 0

Sheet  טבלת סילוקין - לפי מסלולים
B1: טבלת סילוקין - מסלול 1 | K1: טבלת סילוקין - מסלול 2 | T1: טבלת סילוקין - מסלול 3 | AC1: טבלת סילוקין - מסלול 4
B2: פריים | K2: קלצ
B3: מס' | C3: תאריך | D3: יתרת פתיחה | E3: ריבית | F3: קרן | G3: מדד | H3: סך תשלומים | I3: יתרת סגירה | J3: תשלומים שנותרו | K3: מס' | L3: תאריך | M3: יתרת פתיחה | N3: ריבית | O3: קרן | P3: מדד | Q3: סך תשלומים | R3: יתרת סגירה | S3: תשלומים שנותרו | T3: מס' | U3: תאריך | V3: יתרת פתיחה | W3: ריבית | X3: קרן | Y3: מדד | Z3: סך תשלומים | AA3: יתרת סגירה | AB3: תשלומים שנותרו | AC3: מס' | AD3: תאריך | AE3: יתרת פתיחה | AF3: ריבית | AG3: קרן | AH3: מדד | AI3: סך תשלומים | AJ3: יתרת סגירה | AK3: תשלומים שנותרו
B4: =ROWS($B$4:B4) -> 1 | C4: =IF(ValuesEntered,IF(הפחתה[[#This Row],[מס'']]<=תקופת_ההלוואה,IF(ROW()-ROW(הפחתה[[#Headers],[תאריך]])=1,LoanStart,IF(I3>0,EDATE(C3,1),"")),""),"") -> 45383 | D4: =IF(ROW()-ROW(הפחתה[[#Headers],[יתרת פתיחה]])=1,סכום_הלוואה,IF(הפחתה[[#This Row],[תאריך]]="",0,INDEX(הפחתה[], ROW()-4,8))) -> 600000 | E4: =IF(ValuesEntered,IF(ROW()-ROW(הפחתה[[#Headers],[ריבית]])=1,-IPMT(שיעור_ריבית/12,1,תקופת_ההלוואה-ROWS($C$4:C4)+1,הפחתה[[#This Row],[יתרת פתיחה]]),IFERROR(-IPMT(שיעור_ריבית/12,1,הפחתה[[#This Row],[תשלומים שנותרו]],D5),0)),0) -> 2650 | F4: =IFERROR(IF(AND(ValuesEntered,הפחתה[[#This Row],[תאריך]]<>""),-PPMT(שיעור_ריבית/12,1,תקופת_ההלוואה-ROWS($C$4:C4)+1,הפחתה[[#This Row],[יתרת פתיחה]]),""),0) -> 681.82791 | G4: =(הפחתה[[#This Row],[יתרת פתיחה]])*(מדד/12) -> 0 | H4: =IF(הפחתה[[#This Row],[תאריך]]="",0,הפחתה[[#This Row],[ריבית]]+הפחתה[[#This Row],[קרן]]+הפחתה[[#This Row],[מדד]]) -> 3331.8279 | I4: =IF(הפחתה[[#This Row],[תאריך]]="",0,הפחתה[[#This Row],[יתרת פתיחה]]-הפחתה[[#This Row],[קרן]]+הפחתה[[#This Row],[מדד]]) -> 599318.17 | J4: =IF(הפחתה[[#This Row],[יתרת סגירה]]>0,LastRow-ROW(),0) -> 359 | K4: =ROWS($K$4:K4) -> 1 | L4: =IF(ValuesEntered2,IF(הפחתה5[[#This Row],[מס'']]<=תקופת_ההלוואה2,IF(ROW()-ROW(הפחתה5[[#Headers],[תאריך]])=1,LoanStart2,IF(R3>0,EDATE(L3,1),"")),""),"") -> 45383 | M4: =IF(ROW()-ROW(הפחתה5[[#Headers],[יתרת פתיחה]])=1,סכום_הלוואה2,IF(הפחתה5[[#This Row],[תאריך]]="",0,INDEX(הפחתה5[], ROW()-4,8))) -> 300000 | N4: =IF(ValuesEntered2,IF(ROW()-ROW(הפחתה5[[#Headers],[ריבית]])=1,-IPMT(שיעור_ריבית2/12,1,תקופת_ההלוואה2-ROWS($L$4:L4)+1,הפחתה5[[#This Row],[יתרת פתיחה]]),IFERROR(-IPMT(שיעור_ריבית2/12,1,הפחתה5[[#This Row],[תשלומים שנותרו]],M5),0)),0) -> 1175 | O4: =IFERROR(IF(AND(ValuesEntered2,הפחתה5[[#This Row],[תאריך]]<>""),-PPMT(שיעור_ריבית2/12,1,תקופת_ההלוואה2-ROWS($L$4:L4)+1,הפחתה5[[#This Row],[יתרת פתיחה]]),""),0) -> 526.73582 | P4: =(הפחתה5[[#This Row],[יתרת פתיחה]])*(מדד2/12) -> 0 | Q4: =IF(הפחתה5[[#This Row],[תאריך]]="",0,הפחתה5[[#This Row],[ריבית]]+הפחתה5[[#This Row],[קרן]]+הפחתה5[[#This Row],[מדד]]) -> 1701.7358 | R4: =IF(הפחתה5[[#This Row],[תאריך]]="",0,הפחתה5[[#This Row],[יתרת פתיחה]]-הפחתה5[[#This Row],[קרן]]+הפחתה5[[#This Row],[מדד]]) -> 299473.26 | S4: =IF(הפחתה5[[#This Row],[יתרת סגירה]]>0,LastRow2-ROW(),0) -> 299 | T4: =ROWS($T$4:T4) -> 1 | U4: =IF(ValuesEntered3,IF(הפחתה7[[#This Row],[מס'']]<=תקופת_ההלוואה3,IF(ROW()-ROW(הפחתה7[[#Headers],[תאריך]])=1,LoanStart3,IF(AA3>0,EDATE(U3,1),"")),""),"") -> 45621 | V4: =IF(ROW()-ROW(הפחתה7[[#Headers],[יתרת פתיחה]])=1,סכום_הלוואה3,IF(הפחתה7[[#This Row],[תאריך]]="",0,INDEX(הפחתה7[], ROW()-4,8))) -> 100000 | W4: =IF(ValuesEntered3,IF(ROW()-ROW(הפחתה7[[#Headers],[ריבית]])=1,-IPMT(שיעור_ריבית3/12,1,תקופת_ההלוואה3-ROWS($C$4:U4)+1,הפחתה7[[#This Row],[יתרת פתיחה]]),IFERROR(-IPMT(שיעור_ריבית3/12,1,הפחתה7[[#This Row],[תשלומים שנותרו]],V5),0)),0) -> 191.66667 | X4: =IFERROR(IF(AND(ValuesEntered3,הפחתה7[[#This Row],[תאריך]]<>""),-PPMT(שיעור_ריבית3/12,1,תקופת_ההלוואה3-ROWS($C$4:U4)+1,הפחתה7[[#This Row],[יתרת פתיחה]]),""),0) -> 246.94451 | Y4: =(הפחתה7[[#This Row],[יתרת פתיחה]])*(מדד3/12) -> 166.66667 | Z4: =IF(הפחתה7[[#This Row],[תאריך]]="",0,הפחתה7[[#This Row],[ריבית]]+הפחתה7[[#This Row],[קרן]]+הפחתה7[[#This Row],[מדד]]) -> 605.27784 | AA4: =IF(הפחתה7[[#This Row],[תאריך]]="",0,הפחתה7[[#This Row],[יתרת פתיחה]]-הפחתה7[[#This Row],[קרן]]+הפחתה7[[#This Row],[מדד]]) -> 99919.722 | AB4: =IF(הפחתה7[[#This Row],[יתרת סגירה]]>0,LastRow3-ROW(),0) -> 299 | AC4: =ROWS($AC$4:AC4) -> 1 | AD4: =IF(ValuesEntered4,IF(הפחתה8[[#This Row],[מס'']]<=תקופת_ההלוואה4,IF(ROW()-ROW(הפחתה8[[#Headers],[תאריך]])=1,LoanStart4,IF(AJ3>0,EDATE(AD3,1),"")),""),"") | AE4: =IF(ROW()-ROW(הפחתה8[[#Headers],[יתרת פתיחה]])=1,סכום_הלוואה4,IF(הפחתה8[[#This Row],[תאריך]]="",0,INDEX(הפחתה8[], ROW()-4,8))) -> 0 | AF4: =IF(ValuesEntered4,IF(ROW()-ROW(הפחתה8[[#Headers],[ריבית]])=1,-IPMT(שיעור_ריבית4/12,1,תקופת_ההלוואה4-ROWS($C$4:AD4)+1,הפחתה8[[#This Row],[יתרת פתיחה]]),IFERROR(-IPMT(שיעור_ריבית4/12,1,הפחתה8[[#This Row],[תשלומים שנותרו]],AE5),0)),0) -> 0 | AG4: =IFERROR(IF(AND(ValuesEntered4,הפחתה8[[#This Row],[תאריך]]<>""),-PPMT(שיעור_ריבית4/12,1,תקופת_ההלוואה4-ROWS($C$4:AD4)+1,הפחתה8[[#This Row],[יתרת פתיחה]]),""),0) | AH4: =(הפחתה8[[#This Row],[יתרת פתיחה]])*(מדד4/12) -> 0 | AI4: =IF(הפחתה8[[#This Row],[תאריך]]="",0,הפחתה8[[#This Row],[ריבית]]+הפחתה8[[#This Row],[קרן]]+הפחתה8[[#This Row],[מדד]]) -> 0 | AJ4: =IF(הפחתה8[[#This Row],[תאריך]]="",0,הפחתה8[[#This Row],[יתרת פתיחה]]-הפחתה8[[#This Row],[קרן]]) -> 0 | AK4: =IF(הפחתה8[[#This Row],[יתרת סגירה]]>0,LastRow4-ROW(),0) -> 0
B5: =ROWS($B$4:B5) -> 2 | C5: =IF(ValuesEntered,IF(הפחתה[[#This Row],[מס'']]<=תקופת_ההלוואה,IF(ROW()-ROW(הפחתה[[#Headers],[תאריך]])=1,LoanStart,IF(I4>0,EDATE(C4,1),"")),""),"") -> 45413 | D5: =IF(ROW()-ROW(הפחתה[[#Headers],[יתרת פתיחה]])=1,סכום_הלוואה,IF(הפחתה[[#This Row],[תאריך]]="",0,INDEX(הפחתה[], ROW()-4,8))) -> 599318.17 | E5: =IF(ValuesEntered,IF(ROW()-ROW(הפחתה[[#Headers],[ריבית]])=1,-IPMT(שיעור_ריבית/12,1,תקופת_ההלוואה-ROWS($C$4:C5)+1,הפחתה[[#This Row],[יתרת פתיחה]]),IFERROR(-IPMT(שיעור_ריבית/12,1,הפחתה[[#This Row],[תשלומים שנותרו]],D6),0)),0) -> 2643.9639 | F5: =IFERROR(IF(AND(ValuesEntered,הפחתה[[#This Row],[תאריך]]<>""),-PPMT(שיעור_ריבית/12,1,תקופת_ההלוואה-ROWS($C$4:C5)+1,הפחתה[[#This Row],[יתרת פתיחה]]),""),0) -> 684.83932 | G5: =(הפחתה[[#This Row],[יתרת פתיחה]])*(מדד/12) -> 0 | H5: =IF(הפחתה[[#This Row],[תאריך]]="",0,הפחתה[[#This Row],[ריבית]]+הפחתה[[#This Row],[קרן]]+הפחתה[[#This Row],[מדד]]) -> 3328.8032 | I5: =IF(הפחתה[[#This Row],[תאריך]]="",0,הפחתה[[#This Row],[יתרת פתיחה]]-הפחתה[[#This Row],[קרן]]+הפחתה[[#This Row],[מדד]]) -> 598633.33 | J5: =IF(הפחתה[[#This Row],[יתרת סגירה]]>0,LastRow-ROW(),0) -> 358 | K5: =ROWS($K$4:K5) -> 2 | L5: =IF(ValuesEntered2,IF(הפחתה5[[#This Row],[מס'']]<=תקופת_ההלוואה2,IF(ROW()-ROW(הפחתה5[[#Headers],[תאריך]])=1,LoanStart2,IF(R4>0,EDATE(L4,1),"")),""),"") -> 45413 | M5: =IF(ROW()-ROW(הפחתה5[[#Headers],[יתרת פתיחה]])=1,סכום_הלוואה2,IF(הפחתה5[[#This Row],[תאריך]]="",0,INDEX(הפחתה5[], ROW()-4,8))) -> 299473.26 | N5: =IF(ValuesEntered2,IF(ROW()-ROW(הפחתה5[[#Headers],[ריבית]])=1,-IPMT(שיעור_ריבית2/12,1,תקופת_ההלוואה2-ROWS($L$4:L5)+1,הפחתה5[[#This Row],[יתרת פתיחה]]),IFERROR(-IPMT(שיעור_ריבית2/12,1,הפחתה5[[#This Row],[תשלומים שנותרו]],M6),0)),0) -> 1170.8658 | O5: =IFERROR(IF(AND(ValuesEntered2,הפחתה5[[#This Row],[תאריך]]<>""),-PPMT(שיעור_ריבית2/12,1,תקופת_ההלוואה2-ROWS($L$4:L5)+1,הפחתה5[[#This Row],[יתרת פתיחה]]),""),0) -> 528.79887 | P5: =(הפחתה5[[#This Row],[יתרת פתיחה]])*(מדד2/12) -> 0 | Q5: =IF(הפחתה5[[#This Row],[תאריך]]="",0,הפחתה5[[#This Row],[ריבית]]+הפחתה5[[#This Row],[קרן]]+הפחתה5[[#This Row],[מדד]]) -> 1699.6647 | R5: =IF(הפחתה5[[#This Row],[תאריך]]="",0,הפחתה5[[#This Row],[יתרת פתיחה]]-הפחתה5[[#This Row],[קרן]]+הפחתה5[[#This Row],[מדד]]) -> 298944.47 | S5: =IF(הפחתה5[[#This Row],[יתרת סגירה]]>0,LastRow2-ROW(),0) -> 298 | T5: =ROWS($T$4:T5) -> 2 | U5: =IF(ValuesEntered3,IF(הפחתה7[[#This Row],[מס'']]<=תקופת_ההלוואה3,IF(ROW()-ROW(הפחתה7[[#Headers],[תאריך]])=1,LoanStart3,IF(AA4>0,EDATE(U4,1),"")),""),"") -> 45651 | V5: =IF(ROW()-ROW(הפחתה7[[#Headers],[יתרת פתיחה]])=1,סכום_הלוואה3,IF(הפחתה7[[#This Row],[תאריך]]="",0,INDEX(הפחתה7[], ROW()-4,8))) -> 99919.722 | W5: =IF(ValuesEntered3,IF(ROW()-ROW(הפחתה7[[#Headers],[ריבית]])=1,-IPMT(שיעור_ריבית3/12,1,תקופת_ההלוואה3-ROWS($C$4:U5)+1,הפחתה7[[#This Row],[יתרת פתיחה]]),IFERROR(-IPMT(שיעור_ריבית3/12,1,הפחתה7[[#This Row],[תשלומים שנותרו]],V6),0)),0) -> 191.35698 | X5: =IFERROR(IF(AND(ValuesEntered3,הפחתה7[[#This Row],[תאריך]]<>""),-PPMT(שיעור_ריבית3/12,1,תקופת_ההלוואה3-ROWS($C$4:U5)+1,הפחתה7[[#This Row],[יתרת פתיחה]]),""),0) -> 247.8312 | Y5: =(הפחתה7[[#This Row],[יתרת פתיחה]])*(מדד3/12) -> 166.53287 | Z5: =IF(הפחתה7[[#This Row],[תאריך]]="",0,הפחתה7[[#This Row],[ריבית]]+הפחתה7[[#This Row],[קרן]]+הפחתה7[[#This Row],[מדד]]) -> 605.72105 | AA5: =IF(הפחתה7[[#This Row],[תאריך]]="",0,הפחתה7[[#This Row],[יתרת פתיחה]]-הפחתה7[[#This Row],[קרן]]+הפחתה7[[#This Row],[מדד]]) -> 99838.424 | AB5: =IF(הפחתה7[[#This Row],[יתרת סגירה]]>0,LastRow3-ROW(),0) -> 298 | AC5: =ROWS($AC$4:AC5) -> 2 | AD5: =IF(ValuesEntered4,IF(הפחתה8[[#This Row],[מס'']]<=תקופת_ההלוואה4,IF(ROW()-ROW(הפחתה8[[#Headers],[תאריך]])=1,LoanStart4,IF(AJ4>0,EDATE(AD4,1),"")),""),"") | AE5: =IF(ROW()-ROW(הפחתה8[[#Headers],[יתרת פתיחה]])=1,סכום_הלוואה4,IF(הפחתה8[[#This Row],[תאריך]]="",0,INDEX(הפחתה8[], ROW()-4,8))) -> 0 | AF5: =IF(ValuesEntered4,IF(ROW()-ROW(הפחתה8[[#Headers],[ריבית]])=1,-IPMT(שיעור_ריבית4/12,1,תקופת_ההלוואה4-ROWS($C$4:AD5)+1,הפחתה8[[#This Row],[יתרת פתיחה]]),IFERROR(-IPMT(שיעור_ריבית4/12,1,הפחתה8[[#This Row],[תשלומים שנותרו]],AE6),0)),0) -> 0 | AG5: =IFERROR(IF(AND(ValuesEntered4,הפחתה8[[#This Row],[תאריך]]<>""),-PPMT(שיעור_ריבית4/12,1,תקופת_ההלוואה4-ROWS($C$4:AD5)+1,הפחתה8[[#This Row],[יתרת פתיחה]]),""),0) | AH5: =(הפחתה8[[#This Row],[יתרת פתיחה]])*(מדד4/12) -> 0 | AI5: =IF(הפחתה8[[#This Row],[תאריך]]="",0,הפחתה8[[#This Row],[ריבית]]+הפחתה8[[#This Row],[קרן]]+הפחתה8[[#This Row],[מדד]]) -> 0 | AJ5: =IF(הפחתה8[[#This Row],[תאריך]]="",0,הפחתה8[[#This Row],[יתרת פתיחה]]-הפחתה8[[#This Row],[קרן]]) -> 0 | AK5: =IF(הפחתה8[[#This Row],[יתרת סגירה]]>0,LastRow4-ROW(),0) -> 0
B6: =ROWS($B$4:B6) -> 3 | C6: =IF(ValuesEntered,IF(הפחתה[[#This Row],[מס'']]<=תקופת_ההלוואה,IF(ROW()-ROW(הפחתה[[#Headers],[תאריך]])=1,LoanStart,IF(I5>0,EDATE(C5,1),"")),""),"") -> 45444 | D6: =IF(ROW()-ROW(הפחתה[[#Headers],[יתרת פתיחה]])=1,סכום_הלוואה,IF(הפחתה[[#This Row],[תאריך]]="",0,INDEX(הפחתה[], ROW()-4,8))) -> 598633.33 | E6: =IF(ValuesEntered,IF(ROW()-ROW(הפחתה[[#Headers],[ריבית]])=1,-IPMT(שיעור_ריבית/12,1,תקופת_ההלוואה-ROWS($C$4:C6)+1,הפחתה[[#This Row],[יתרת פתיחה]]),IFERROR(-IPMT(שיעור_ריבית/12,1,הפחתה[[#This Row],[תשלומים שנותרו]],D7),0)),0) -> 2640.9258 | F6: =IFERROR(IF(AND(ValuesEntered,הפחתה[[#This Row],[תאריך]]<>""),-PPMT(שיעור_ריבית/12,1,תקופת_ההלוואה-ROWS($C$4:C6)+1,הפחתה[[#This Row],[יתרת פתיחה]]),""),0) -> 687.86403 | G6: =(הפחתה[[#This Row],[יתרת פתיחה]])*(מדד/12) -> 0 | H6: =IF(הפחתה[[#This Row],[תאריך]]="",0,הפחתה[[#This Row],[ריבית]]+הפחתה[[#This Row],[קרן]]+הפחתה[[#This Row],[מדד]]) -> 3328.7898 | I6: =IF(הפחתה[[#This Row],[תאריך]]="",0,הפחתה[[#This Row],[יתרת פתיחה]]-הפחתה[[#This Row],[קרן]]+הפחתה[[#This Row],[מדד]]) -> 597945.47 | J6: =IF(הפחתה[[#This Row],[יתרת סגירה]]>0,LastRow-ROW(),0) -> 357 | K6: =ROWS($K$4:K6) -> 3 | L6: =IF(ValuesEntered2,IF(הפחתה5[[#This Row],[מס'']]<=תקופת_ההלוואה2,IF(ROW()-ROW(הפחתה5[[#Headers],[תאריך]])=1,LoanStart2,IF(R5>0,EDATE(L5,1),"")),""),"") -> 45444 | M6: =IF(ROW()-ROW(הפחתה5[[#Headers],[יתרת פתיחה]])=1,סכום_הלוואה2,IF(הפחתה5[[#This Row],[תאריך]]="",0,INDEX(הפחתה5[], ROW()-4,8))) -> 298944.47 | N6: =IF(ValuesEntered2,IF(ROW()-ROW(הפחתה5[[#Headers],[ריבית]])=1,-IPMT(שיעור_ריבית2/12,1,תקופת_ההלוואה2-ROWS($L$4:L6)+1,הפחתה5[[#This Row],[יתרת פתיחה]]),IFERROR(-IPMT(שיעור_ריבית2/12,1,הפחתה5[[#This Row],[תשלומים שנותרו]],M7),0)),0) -> 1168.7866 | O6: =IFERROR(IF(AND(ValuesEntered2,הפחתה5[[#This Row],[תאריך]]<>""),-PPMT(שיעור_ריבית2/12,1,תקופת_ההלוואה2-ROWS($L$4:L6)+1,הפחתה5[[#This Row],[יתרת פתיחה]]),""),0) -> 530.87 | P6: =(הפחתה5[[#This Row],[יתרת פתיחה]])*(מדד2/12) -> 0 | Q6: =IF(הפחתה5[[#This Row],[תאריך]]="",0,הפחתה5[[#This Row],[ריבית]]+הפחתה5[[#This Row],[קרן]]+הפחתה5[[#This Row],[מדד]]) -> 1699.6566 | R6: =IF(הפחתה5[[#This Row],[תאריך]]="",0,הפחתה5[[#This Row],[יתרת פתיחה]]-הפחתה5[[#This Row],[קרן]]+הפחתה5[[#This Row],[מדד]]) -> 298413.6 | S6: =IF(הפחתה5[[#This Row],[יתרת סגירה]]>0,LastRow2-ROW(),0) -> 297 | T6: =ROWS($T$4:T6) -> 3 | U6: =IF(ValuesEntered3,IF(הפחתה7[[#This Row],[מס'']]<=תקופת_ההלוואה3,IF(ROW()-ROW(הפחתה7[[#Headers],[תאריך]])=1,LoanStart3,IF(AA5>0,EDATE(U5,1),"")),""),"") -> 45682 | V6: =IF(ROW()-ROW(הפחתה7[[#Headers],[יתרת פתיחה]])=1,סכום_הלוואה3,IF(הפחתה7[[#This Row],[תאריך]]="",0,INDEX(הפחתה7[], ROW()-4,8))) -> 99838.424 | W6: =IF(ValuesEntered3,IF(ROW()-ROW(הפחתה7[[#Headers],[ריבית]])=1,-IPMT(שיעור_ריבית3/12,1,תקופת_ההלוואה3-ROWS($C$4:U6)+1,הפחתה7[[#This Row],[יתרת פתיחה]]),IFERROR(-IPMT(שיעור_ריבית3/12,1,הפחתה7[[#This Row],[תשלומים שנותרו]],V7),0)),0) -> 191.19919 | X6: =IFERROR(IF(AND(ValuesEntered3,הפחתה7[[#This Row],[תאריך]]<>""),-PPMT(שיעור_ריבית3/12,1,תקופת_ההלוואה3-ROWS($C$4:U6)+1,הפחתה7[[#This Row],[יתרת פתיחה]]),""),0) -> 248.72109 | Y6: =(הפחתה7[[#This Row],[יתרת פתיחה]])*(מדד3/12) -> 166.39737 | Z6: =IF(הפחתה7[[#This Row],[תאריך]]="",0,הפחתה7[[#This Row],[ריבית]]+הפחתה7[[#This Row],[קרן]]+הפחתה7[[#This Row],[מדד]]) -> 606.31765 | AA6: =IF(הפחתה7[[#This Row],[תאריך]]="",0,הפחתה7[[#This Row],[יתרת פתיחה]]-הפחתה7[[#This Row],[קרן]]+הפחתה7[[#This Row],[מדד]]) -> 99756.1 | AB6: =IF(הפחתה7[[#This Row],[יתרת סגירה]]>0,LastRow3-ROW(),0) -> 297 | AC6: =ROWS($AC$4:AC6) -> 3 | AD6: =IF(ValuesEntered4,IF(הפחתה8[[#This Row],[מס'']]<=תקופת_ההלוואה4,IF(ROW()-ROW(הפחתה8[[#Headers],[תאריך]])=1,LoanStart4,IF(AJ5>0,EDATE(AD5,1),"")),""),"") | AE6: =IF(ROW()-ROW(הפחתה8[[#Headers],[יתרת פתיחה]])=1,סכום_הלוואה4,IF(הפחתה8[[#This Row],[תאריך]]="",0,INDEX(הפחתה8[], ROW()-4,8))) -> 0 | AF6: =IF(ValuesEntered4,IF(ROW()-ROW(הפחתה8[[#Headers],[ריבית]])=1,-IPMT(שיעור_ריבית4/12,1,תקופת_ההלוואה4-ROWS($C$4:AD6)+1,הפחתה8[[#This Row],[יתרת פתיחה]]),IFERROR(-IPMT(שיעור_ריבית4/12,1,הפחתה8[[#This Row],[תשלומים שנותרו]],AE7),0)),0) -> 0 | AG6: =IFERROR(IF(AND(ValuesEntered4,הפחתה8[[#This Row],[תאריך]]<>""),-PPMT(שיעור_ריבית4/12,1,תקופת_ההלוואה4-ROWS($C$4:AD6)+1,הפחתה8[[#This Row],[יתרת פתיחה]]),""),0) | AH6: =(הפחתה8[[#This Row],[יתרת פתיחה]])*(מדד4/12) -> 0 | AI6: =IF(הפחתה8[[#This Row],[תאריך]]="",0,הפחתה8[[#This Row],[ריבית]]+הפחתה8[[#This Row],[קרן]]+הפחתה8[[#This Row],[מדד]]) -> 0 | AJ6: =IF(הפחתה8[[#This Row],[תאריך]]="",0,הפחתה8[[#This Row],[יתרת פתיחה]]-הפחתה8[[#This Row],[קרן]]) -> 0 | AK6: =IF(הפחתה8[[#This Row],[יתרת סגירה]]>0,LastRow4-ROW(),0) -> 0
B7: =ROWS($B$4:B7) -> 4 | C7: =IF(ValuesEntered,IF(הפחתה[[#This Row],[מס'']]<=תקופת_ההלוואה,IF(ROW()-ROW(הפחתה[[#Headers],[תאריך]])=1,LoanStart,IF(I6>0,EDATE(C6,1),"")),""),"") -> 45474 | D7: =IF(ROW()-ROW(הפחתה[[#Headers],[יתרת פתיחה]])=1,סכום_הלוואה,IF(הפחתה[[#This Row],[תאריך]]="",0,INDEX(הפחתה[], ROW()-4,8))) -> 597945.47 | E7: =IF(ValuesEntered,IF(ROW()-ROW(הפחתה[[#Headers],[ריבית]])=1,-IPMT(שיעור_ריבית/12,1,תקופת_ההלוואה-ROWS($C$4:C7)+1,הפחתה[[#This Row],[יתרת פתיחה]]),IFERROR(-IPMT(שיעור_ריבית/12,1,הפחתה[[#This Row],[תשלומים שנותרו]],D8),0)),0) -> 2637.8743 | F7: =IFERROR(IF(AND(ValuesEntered,הפחתה[[#This Row],[תאריך]]<>""),-PPMT(שיעור_ריבית/12,1,תקופת_ההלוואה-ROWS($C$4:C7)+1,הפחתה[[#This Row],[יתרת פתיחה]]),""),0) -> 690.90209 | G7: =(הפחתה[[#This Row],[יתרת פתיחה]])*(מדד/12) -> 0 | H7: =IF(הפחתה[[#This Row],[תאריך]]="",0,הפחתה[[#This Row],[ריבית]]+הפחתה[[#This Row],[קרן]]+הפחתה[[#This Row],[מדד]]) -> 3328.7764 | I7: =IF(הפחתה[[#This Row],[תאריך]]="",0,הפחתה[[#This Row],[יתרת פתיחה]]-הפחתה[[#This Row],[קרן]]+הפחתה[[#This Row],[מדד]]) -> 597254.57 | J7: =IF(הפחתה[[#This Row],[יתרת סגירה]]>0,LastRow-ROW(),0) -> 356 | K7: =ROWS($K$4:K7) -> 4 | L7: =IF(ValuesEntered2,IF(הפחתה5[[#This Row],[מס'']]<=תקופת_ההלוואה2,IF(ROW()-ROW(הפחתה5[[#Headers],[תאריך]])=1,LoanStart2,IF(R6>0,EDATE(L6,1),"")),""),"") -> 45474 | M7: =IF(ROW()-ROW(הפחתה5[[#Headers],[יתרת פתיחה]])=1,סכום_הלוואה2,IF(הפחתה5[[#This Row],[תאריך]]="",0,INDEX(הפחתה5[], ROW()-4,8))) -> 298413.6 | N7: =IF(ValuesEntered2,IF(ROW()-ROW(הפחתה5[[#Headers],[ריבית]])=1,-IPMT(שיעור_ריבית2/12,1,תקופת_ההלוואה2-ROWS($L$4:L7)+1,הפחתה5[[#This Row],[יתרת פתיחה]]),IFERROR(-IPMT(שיעור_ריבית2/12,1,הפחתה5[[#This Row],[תשלומים שנותרו]],M8),0)),0) -> 1166.6992 | O7: =IFERROR(IF(AND(ValuesEntered2,הפחתה5[[#This Row],[תאריך]]<>""),-PPMT(שיעור_ריבית2/12,1,תקופת_ההלוואה2-ROWS($L$4:L7)+1,הפחתה5[[#This Row],[יתרת פתיחה]]),""),0) -> 532.94924 | P7: =(הפחתה5[[#This Row],[יתרת פתיחה]])*(מדד2/12) -> 0 | Q7: =IF(הפחתה5[[#This Row],[תאריך]]="",0,הפחתה5[[#This Row],[ריבית]]+הפחתה5[[#This Row],[קרן]]+הפחתה5[[#This Row],[מדד]]) -> 1699.6484 | R7: =IF(הפחתה5[[#This Row],[תאריך]]="",0,הפחתה5[[#This Row],[יתרת פתיחה]]-הפחתה5[[#This Row],[קרן]]+הפחתה5[[#This Row],[מדד]]) -> 297880.65 | S7: =IF(הפחתה5[[#This Row],[יתרת סגירה]]>0,LastRow2-ROW(),0) -> 296 | T7: =ROWS($T$4:T7) -> 4 | U7: =IF(ValuesEntered3,IF(הפחתה7[[#This Row],[מס'']]<=תקופת_ההלוואה3,IF(ROW()-ROW(הפחתה7[[#Headers],[תאריך]])=1,LoanStart3,IF(AA6>0,EDATE(U6,1),"")),""),"") -> 45713 | V7: =IF(ROW()-ROW(הפחתה7[[#Headers],[יתרת פתיחה]])=1,סכום_הלוואה3,IF(הפחתה7[[#This Row],[תאריך]]="",0,INDEX(הפחתה7[], ROW()-4,8))) -> 99756.1 | W7: =IF(ValuesEntered3,IF(ROW()-ROW(הפחתה7[[#Headers],[ריבית]])=1,-IPMT(שיעור_ריבית3/12,1,תקופת_ההלוואה3-ROWS($C$4:U7)+1,הפחתה7[[#This Row],[יתרת פתיחה]]),IFERROR(-IPMT(שיעור_ריבית3/12,1,הפחתה7[[#This Row],[תשלומים שנותרו]],V8),0)),0) -> 191.03943 | X7: =IFERROR(IF(AND(ValuesEntered3,הפחתה7[[#This Row],[תאריך]]<>""),-PPMT(שיעור_ריבית3/12,1,תקופת_ההלוואה3-ROWS($C$4:U7)+1,הפחתה7[[#This Row],[יתרת פתיחה]]),""),0) -> 249.61417 | Y7: =(הפחתה7[[#This Row],[יתרת פתיחה]])*(מדד3/12) -> 166.26017 | Z7: =IF(הפחתה7[[#This Row],[תאריך]]="",0,הפחתה7[[#This Row],[ריבית]]+הפחתה7[[#This Row],[קרן]]+הפחתה7[[#This Row],[מדד]]) -> 606.91377 | AA7: =IF(הפחתה7[[#This Row],[תאריך]]="",0,הפחתה7[[#This Row],[יתרת פתיחה]]-הפחתה7[[#This Row],[קרן]]+הפחתה7[[#This Row],[מדד]]) -> 99672.746 | AB7: =IF(הפחתה7[[#This Row],[יתרת סגירה]]>0,LastRow3-ROW(),0) -> 296 | AC7: =ROWS($AC$4:AC7) -> 4 | AD7: =IF(ValuesEntered4,IF(הפחתה8[[#This Row],[מס'']]<=תקופת_ההלוואה4,IF(ROW()-ROW(הפחתה8[[#Headers],[תאריך]])=1,LoanStart4,IF(AJ6>0,EDATE(AD6,1),"")),""),"") | AE7: =IF(ROW()-ROW(הפחתה8[[#Headers],[יתרת פתיחה]])=1,סכום_הלוואה4,IF(הפחתה8[[#This Row],[תאריך]]="",0,INDEX(הפחתה8[], ROW()-4,8))) -> 0 | AF7: =IF(ValuesEntered4,IF(ROW()-ROW(הפחתה8[[#Headers],[ריבית]])=1,-IPMT(שיעור_ריבית4/12,1,תקופת_ההלוואה4-ROWS($C$4:AD7)+1,הפחתה8[[#This Row],[יתרת פתיחה]]),IFERROR(-IPMT(שיעור_ריבית4/12,1,הפחתה8[[#This Row],[תשלומים שנותרו]],AE8),0)),0) -> 0 | AG7: =IFERROR(IF(AND(ValuesEntered4,הפחתה8[[#This Row],[תאריך]]<>""),-PPMT(שיעור_ריבית4/12,1,תקופת_ההלוואה4-ROWS($C$4:AD7)+1,הפחתה8[[#This Row],[יתרת פתיחה]]),""),0) | AH7: =(הפחתה8[[#This Row],[יתרת פתיחה]])*(מדד4/12) -> 0 | AI7: =IF(הפחתה8[[#This Row],[תאריך]]="",0,הפחתה8[[#This Row],[ריבית]]+הפחתה8[[#This Row],[קרן]]+הפחתה8[[#This Row],[מדד]]) -> 0 | AJ7: =IF(הפחתה8[[#This Row],[תאריך]]="",0,הפחתה8[[#This Row],[יתרת פתיחה]]-הפחתה8[[#This Row],[קרן]]) -> 0 | AK7: =IF(הפחתה8[[#This Row],[יתרת סגירה]]>0,LastRow4-ROW(),0) -> 0
B8: =ROWS($B$4:B8) -> 5 | C8: =IF(ValuesEntered,IF(הפחתה[[#This Row],[מס'']]<=תקופת_ההלוואה,IF(ROW()-ROW(הפחתה[[#Headers],[תאריך]])=1,LoanStart,IF(I7>0,EDATE(C7,1),"")),""),"") -> 45505 | D8: =IF(ROW()-ROW(הפחתה[[#Headers],[יתרת פתיחה]])=1,סכום_הלוואה,IF(הפחתה[[#This Row],[תאריך]]="",0,INDEX(הפחתה[], ROW()-4,8))) -> 597254.57 | E8: =IF(ValuesEntered,IF(ROW()-ROW(הפחתה[[#Headers],[ריבית]])=1,-IPMT(שיעור_ריבית/12,1,תקופת_ההלוואה-ROWS($C$4:C8)+1,הפחתה[[#This Row],[יתרת פתיחה]]),IFERROR(-IPMT(שיעור_ריבית/12,1,הפחתה[[#This Row],[תשלומים שנותרו]],D9),0)),0) -> 2634.8094 | F8: =IFERROR(IF(AND(ValuesEntered,הפחתה[[#This Row],[תאריך]]<>""),-PPMT(שיעור_ריבית/12,1,תקופת_ההלוואה-ROWS($C$4:C8)+1,הפחתה[[#This Row],[יתרת פתיחה]]),""),0) -> 693.95358 | G8: =(הפחתה[[#This Row],[יתרת פתיחה]])*(מדד/12) -> 0 | H8: =IF(הפחתה[[#This Row],[תאריך]]="",0,הפחתה[[#This Row],[ריבית]]+הפחתה[[#This Row],[קרן]]+הפחתה[[#This Row],[מדד]]) -> 3328.763 | I8: =IF(הפחתה[[#This Row],[תאריך]]="",0,הפחתה[[#This Row],[יתרת פתיחה]]-הפחתה[[#This Row],[קרן]]+הפחתה[[#This Row],[מדד]]) -> 596560.61 | J8: =IF(הפחתה[[#This Row],[יתרת סגירה]]>0,LastRow-ROW(),0) -> 355 | K8: =ROWS($K$4:K8) -> 5 | L8: =IF(ValuesEntered2,IF(הפחתה5[[#This Row],[מס'']]<=תקופת_ההלוואה2,IF(ROW()-ROW(הפחתה5[[#Headers],[תאריך]])=1,LoanStart2,IF(R7>0,EDATE(L7,1),"")),""),"") -> 45505 | M8: =IF(ROW()-ROW(הפחתה5[[#Headers],[יתרת פתיחה]])=1,סכום_הלוואה2,IF(הפחתה5[[#This Row],[תאריך]]="",0,INDEX(הפחתה5[], ROW()-4,8))) -> 297880.65 | N8: =IF(ValuesEntered2,IF(ROW()-ROW(הפחתה5[[#Headers],[ריבית]])=1,-IPMT(שיעור_ריבית2/12,1,תקופת_ההלוואה2-ROWS($L$4:L8)+1,הפחתה5[[#This Row],[יתרת פתיחה]]),IFERROR(-IPMT(שיעור_ריבית2/12,1,הפחתה5[[#This Row],[תשלומים שנותרו]],M9),0)),0) -> 1164.6036 | O8: =IFERROR(IF(AND(ValuesEntered2,הפחתה5[[#This Row],[תאריך]]<>""),-PPMT(שיעור_ריבית2/12,1,תקופת_ההלוואה2-ROWS($L$4:L8)+1,הפחתה5[[#This Row],[יתרת פתיחה]]),""),0) -> 535.03662 | P8: =(הפחתה5[[#This Row],[יתרת פתיחה]])*(מדד2/12) -> 0 | Q8: =IF(הפחתה5[[#This Row],[תאריך]]="",0,הפחתה5[[#This Row],[ריבית]]+הפחתה5[[#This Row],[קרן]]+הפחתה5[[#This Row],[מדד]]) -> 1699.6403 | R8: =IF(הפחתה5[[#This Row],[תאריך]]="",0,הפחתה5[[#This Row],[יתרת פתיחה]]-הפחתה5[[#This Row],[קרן]]+הפחתה5[[#This Row],[מדד]]) -> 297345.61 | S8: =IF(הפחתה5[[#This Row],[יתרת סגירה]]>0,LastRow2-ROW(),0) -> 295 | T8: =ROWS($T$4:T8) -> 5 | U8: =IF(ValuesEntered3,IF(הפחתה7[[#This Row],[מס'']]<=תקופת_ההלוואה3,IF(ROW()-ROW(הפחתה7[[#Headers],[תאריך]])=1,LoanStart3,IF(AA7>0,EDATE(U7,1),"")),""),"") -> 45741 | V8: =IF(ROW()-ROW(הפחתה7[[#Headers],[יתרת פתיחה]])=1,סכום_הלוואה3,IF(הפחתה7[[#This Row],[תאריך]]="",0,INDEX(הפחתה7[], ROW()-4,8))) -> 99672.746 | W8: =IF(ValuesEntered3,IF(ROW()-ROW(הפחתה7[[#Headers],[ריבית]])=1,-IPMT(שיעור_ריבית3/12,1,תקופת_ההלוואה3-ROWS($C$4:U8)+1,הפחתה7[[#This Row],[יתרת פתיחה]]),IFERROR(-IPMT(שיעור_ריבית3/12,1,הפחתה7[[#This Row],[תשלומים שנותרו]],V9),0)),0) -> 190.87768 | X8: =IFERROR(IF(AND(ValuesEntered3,הפחתה7[[#This Row],[תאריך]]<>""),-PPMT(שיעור_ריבית3/12,1,תקופת_ההלוואה3-ROWS($C$4:U8)+1,הפחתה7[[#This Row],[יתרת פתיחה]]),""),0) -> 250.51046 | Y8: =(הפחתה7[[#This Row],[יתרת פתיחה]])*(מדד3/12) -> 166.12124 | Z8: =IF(הפחתה7[[#This Row],[תאריך]]="",0,הפחתה7[[#This Row],[ריבית]]+הפחתה7[[#This Row],[קרן]]+הפחתה7[[#This Row],[מדד]]) -> 607.50939 | AA8: =IF(הפחתה7[[#This Row],[תאריך]]="",0,הפחתה7[[#This Row],[יתרת פתיחה]]-הפחתה7[[#This Row],[קרן]]+הפחתה7[[#This Row],[מדד]]) -> 99588.357 | AB8: =IF(הפחתה7[[#This Row],[יתרת סגירה]]>0,LastRow3-ROW(),0) -> 295 | AC8: =ROWS($AC$4:AC8) -> 5 | AD8: =IF(ValuesEntered4,IF(הפחתה8[[#This Row],[מס'']]<=תקופת_ההלוואה4,IF(ROW()-ROW(הפחתה8[[#Headers],[תאריך]])=1,LoanStart4,IF(AJ7>0,EDATE(AD7,1),"")),""),"") | AE8: =IF(ROW()-ROW(הפחתה8[[#Headers],[יתרת פתיחה]])=1,סכום_הלוואה4,IF(הפחתה8[[#This Row],[תאריך]]="",0,INDEX(הפחתה8[], ROW()-4,8))) -> 0 | AF8: =IF(ValuesEntered4,IF(ROW()-ROW(הפחתה8[[#Headers],[ריבית]])=1,-IPMT(שיעור_ריבית4/12,1,תקופת_ההלוואה4-ROWS($C$4:AD8)+1,הפחתה8[[#This Row],[יתרת פתיחה]]),IFERROR(-IPMT(שיעור_ריבית4/12,1,הפחתה8[[#This Row],[תשלומים שנותרו]],AE9),0)),0) -> 0 | AG8: =IFERROR(IF(AND(ValuesEntered4,הפחתה8[[#This Row],[תאריך]]<>""),-PPMT(שיעור_ריבית4/12,1,תקופת_ההלוואה4-ROWS($C$4:AD8)+1,הפחתה8[[#This Row],[יתרת פתיחה]]),""),0) | AH8: =(הפחתה8[[#This Row],[יתרת פתיחה]])*(מדד4/12) -> 0 | AI8: =IF(הפחתה8[[#This Row],[תאריך]]="",0,הפחתה8[[#This Row],[ריבית]]+הפחתה8[[#This Row],[קרן]]+הפחתה8[[#This Row],[מדד]]) -> 0 | AJ8: =IF(הפחתה8[[#This Row],[תאריך]]="",0,הפחתה8[[#This Row],[יתרת פתיחה]]-הפחתה8[[#This Row],[קרן]]) -> 0 | AK8: =IF(הפחתה8[[#This Row],[יתרת סגירה]]>0,LastRow4-ROW(),0) -> 0
B9: =ROWS($B$4:B9) -> 6 | C9: =IF(ValuesEntered,IF(הפחתה[[#This Row],[מס'']]<=תקופת_ההלוואה,IF(ROW()-ROW(הפחתה[[#Headers],[תאריך]])=1,LoanStart,IF(I8>0,EDATE(C8,1),"")),""),"") -> 45536 | D9: =IF(ROW()-ROW(הפחתה[[#Headers],[יתרת פתיחה]])=1,סכום_הלוואה,IF(הפחתה[[#This Row],[תאריך]]="",0,INDEX(הפחתה[], ROW()-4,8))) -> 596560.61 | E9: =IF(ValuesEntered,IF(ROW()-ROW(הפחתה[[#Headers],[ריבית]])=1,-IPMT(שיעור_ריבית/12,1,תקופת_ההלוואה-ROWS($C$4:C9)+1,הפחתה[[#This Row],[יתרת פתיחה]]),IFERROR(-IPMT(שיעור_ריבית/12,1,הפחתה[[#This Row],[תשלומים שנותרו]],D10),0)),0) -> 2631.7309 | F9: =IFERROR(IF(AND(ValuesEntered,הפחתה[[#This Row],[תאריך]]<>""),-PPMT(שיעור_ריבית/12,1,תקופת_ההלוואה-ROWS($C$4:C9)+1,הפחתה[[#This Row],[יתרת פתיחה]]),""),0) -> 697.01854 | G9: =(הפחתה[[#This Row],[יתרת פתיחה]])*(מדד/12) -> 0 | H9: =IF(הפחתה[[#This Row],[תאריך]]="",0,הפחתה[[#This Row],[ריבית]]+הפחתה[[#This Row],[קרן]]+הפחתה[[#This Row],[מדד]]) -> 3328.7494 | I9: =IF(הפחתה[[#This Row],[תאריך]]="",0,הפחתה[[#This Row],[יתרת פתיחה]]-הפחתה[[#This Row],[קרן]]+הפחתה[[#This Row],[מדד]]) -> 595863.59 | J9: =IF(הפחתה[[#This Row],[יתרת סגירה]]>0,LastRow-ROW(),0) -> 354 | K9: =ROWS($K$4:K9) -> 6 | L9: =IF(ValuesEntered2,IF(הפחתה5[[#This Row],[מס'']]<=תקופת_ההלוואה2,IF(ROW()-ROW(הפחתה5[[#Headers],[תאריך]])=1,LoanStart2,IF(R8>0,EDATE(L8,1),"")),""),"") -> 45536 | M9: =IF(ROW()-ROW(הפחתה5[[#Headers],[יתרת פתיחה]])=1,סכום_הלוואה2,IF(הפחתה5[[#This Row],[תאריך]]="",0,INDEX(הפחתה5[], ROW()-4,8))) -> 297345.61 | N9: =IF(ValuesEntered2,IF(ROW()-ROW(הפחתה5[[#Headers],[ריבית]])=1,-IPMT(שיעור_ריבית2/12,1,תקופת_ההלוואה2-ROWS($L$4:L9)+1,הפחתה5[[#This Row],[יתרת פתיחה]]),IFERROR(-IPMT(שיעור_ריבית2/12,1,הפחתה5[[#This Row],[תשלומים שנותרו]],M10),0)),0) -> 1162.4999 | O9: =IFERROR(IF(AND(ValuesEntered2,הפחתה5[[#This Row],[תאריך]]<>""),-PPMT(שיעור_ריבית2/12,1,תקופת_ההלוואה2-ROWS($L$4:L9)+1,הפחתה5[[#This Row],[יתרת פתיחה]]),""),0) -> 537.13218 | P9: =(הפחתה5[[#This Row],[יתרת פתיחה]])*(מדד2/12) -> 0 | Q9: =IF(הפחתה5[[#This Row],[תאריך]]="",0,הפחתה5[[#This Row],[ריבית]]+הפחתה5[[#This Row],[קרן]]+הפחתה5[[#This Row],[מדד]]) -> 1699.6321 | R9: =IF(הפחתה5[[#This Row],[תאריך]]="",0,הפחתה5[[#This Row],[יתרת פתיחה]]-הפחתה5[[#This Row],[קרן]]+הפחתה5[[#This Row],[מדד]]) -> 296808.48 | S9: =IF(הפחתה5[[#This Row],[יתרת סגירה]]>0,LastRow2-ROW(),0) -> 294 | T9: =ROWS($T$4:T9) -> 6 | U9: =IF(ValuesEntered3,IF(הפחתה7[[#This Row],[מס'']]<=תקופת_ההלוואה3,IF(ROW()-ROW(הפחתה7[[#Headers],[תאריך]])=1,LoanStart3,IF(AA8>0,EDATE(U8,1),"")),""),"") -> 45772 | V9: =IF(ROW()-ROW(הפחתה7[[#Headers],[יתרת פתיחה]])=1,סכום_הלוואה3,IF(הפחתה7[[#This Row],[תאריך]]="",0,INDEX(הפחתה7[], ROW()-4,8))) -> 99588.357 | W9: =IF(ValuesEntered3,IF(ROW()-ROW(הפחתה7[[#Headers],[ריבית]])=1,-IPMT(שיעור_ריבית3/12,1,תקופת_ההלוואה3-ROWS($C$4:U9)+1,הפחתה7[[#This Row],[יתרת פתיחה]]),IFERROR(-IPMT(שיעור_ריבית3/12,1,הפחתה7[[#This Row],[תשלומים שנותרו]],V10),0)),0) -> 190.71394 | X9: =IFERROR(IF(AND(ValuesEntered3,הפחתה7[[#This Row],[תאריך]]<>""),-PPMT(שיעור_ריבית3/12,1,תקופת_ההלוואה3-ROWS($C$4:U9)+1,הפחתה7[[#This Row],[יתרת פתיחה]]),""),0) -> 251.40998 | Y9: =(הפחתה7[[#This Row],[יתרת פתיחה]])*(מדד3/12) -> 165.98059 | Z9: =IF(הפחתה7[[#This Row],[תאריך]]="",0,הפחתה7[[#This Row],[ריבית]]+הפחתה7[[#This Row],[קרן]]+הפחתה7[[#This Row],[מדד]]) -> 608.10452 | AA9: =IF(הפחתה7[[#This Row],[תאריך]]="",0,הפחתה7[[#This Row],[יתרת פתיחה]]-הפחתה7[[#This Row],[קרן]]+הפחתה7[[#This Row],[מדד]]) -> 99502.927 | AB9: =IF(הפחתה7[[#This Row],[יתרת סגירה]]>0,LastRow3-ROW(),0) -> 294 | AC9: =ROWS($AC$4:AC9) -> 6 | AD9: =IF(ValuesEntered4,IF(הפחתה8[[#This Row],[מס'']]<=תקופת_ההלוואה4,IF(ROW()-ROW(הפחתה8[[#Headers],[תאריך]])=1,LoanStart4,IF(AJ8>0,EDATE(AD8,1),"")),""),"") | AE9: =IF(ROW()-ROW(הפחתה8[[#Headers],[יתרת פתיחה]])=1,סכום_הלוואה4,IF(הפחתה8[[#This Row],[תאריך]]="",0,INDEX(הפחתה8[], ROW()-4,8))) -> 0 | AF9: =IF(ValuesEntered4,IF(ROW()-ROW(הפחתה8[[#Headers],[ריבית]])=1,-IPMT(שיעור_ריבית4/12,1,תקופת_ההלוואה4-ROWS($C$4:AD9)+1,הפחתה8[[#This Row],[יתרת פתיחה]]),IFERROR(-IPMT(שיעור_ריבית4/12,1,הפחתה8[[#This Row],[תשלומים שנותרו]],AE10),0)),0) -> 0 | AG9: =IFERROR(IF(AND(ValuesEntered4,הפחתה8[[#This Row],[תאריך]]<>""),-PPMT(שיעור_ריבית4/12,1,תקופת_ההלוואה4-ROWS($C$4:AD9)+1,הפחתה8[[#This Row],[יתרת פתיחה]]),""),0) | AH9: =(הפחתה8[[#This Row],[יתרת פתיחה]])*(מדד4/12) -> 0 | AI9: =IF(הפחתה8[[#This Row],[תאריך]]="",0,הפחתה8[[#This Row],[ריבית]]+הפחתה8[[#This Row],[קרן]]+הפחתה8[[#This Row],[מדד]]) -> 0 | AJ9: =IF(הפחתה8[[#This Row],[תאריך]]="",0,הפחתה8[[#This Row],[יתרת פתיחה]]-הפחתה8[[#This Row],[קרן]]) -> 0 | AK9: =IF(הפחתה8[[#This Row],[יתרת סגירה]]>0,LastRow4-ROW(),0) -> 0
